2016-07-25 11:20:47,940 [Thread-12:-1303286976] [django.request:182] [base:get_response] [WARNING]- Not Found: /metamap/style.css
2016-07-25 11:20:49,626 [Thread-15:-1303286976] [django.request:182] [base:get_response] [WARNING]- Not Found: /metamap/etls/execlog/23/style.css
2016-07-25 11:21:14,808 [Thread-27:-1303286976] [django.request:182] [base:get_response] [WARNING]- Not Found: /metamap/style.css
2016-07-25 11:21:16,123 [Thread-31:-1277060288] [django.request:182] [base:get_response] [WARNING]- Not Found: /metamap/etls/execlog/24/style.css
2016-07-25 11:21:28,920 [Thread-39:-1285715136] [django.request:182] [base:get_response] [WARNING]- Not Found: /metamap/style.css
2016-07-25 11:21:30,843 [Thread-42:-1313518784] [django.request:182] [base:get_response] [WARNING]- Not Found: /metamap/etls/execlog/25/style.css
2016-07-25 11:22:24,454 [Thread-13:-1313256640] [django.request:182] [base:get_response] [WARNING]- Not Found: /metamap/style.css
2016-07-25 11:22:26,889 [Thread-17:-1303286976] [django.request:182] [base:get_response] [WARNING]- Not Found: /metamap/etls/execlog/26/style.css
2016-07-25 11:23:16,804 [Thread-44:-1277060288] [django.request:182] [base:get_response] [WARNING]- Not Found: /metamap/etls/execlog/26/style.css
2016-07-25 11:23:19,257 [Thread-50:-1277060288] [django.request:182] [base:get_response] [WARNING]- Not Found: /metamap/etls/execlog/26/style.css
2016-07-25 11:24:08,304 [Thread-15:-1304073408] [django.request:182] [base:get_response] [WARNING]- Not Found: /metamap/style.css
2016-07-25 11:24:10,196 [Thread-18:-1314043072] [django.request:182] [base:get_response] [WARNING]- Not Found: /metamap/etls/execlog/27/style.css
2016-07-25 11:24:18,021 [Thread-24:-1314043072] [django.request:182] [base:get_response] [WARNING]- Not Found: /metamap/etls/execlog/27/style.css
2016-07-25 11:26:27,958 [Thread-13:-1313518784] [django.request:182] [base:get_response] [WARNING]- Not Found: /metamap/style.css
2016-07-25 11:26:30,457 [Thread-16:-1303286976] [django.request:182] [base:get_response] [WARNING]- Not Found: /metamap/etls/execlog/28/style.css
2016-07-25 11:26:47,852 [Thread-26:-1303286976] [django.request:182] [base:get_response] [WARNING]- Not Found: /metamap/style.css
2016-07-25 11:26:51,558 [Thread-28:-1303286976] [django.request:182] [base:get_response] [WARNING]- Not Found: /metamap/etls/execlog/22/style.css
2016-07-25 11:26:52,805 [Thread-31:-1303286976] [django.request:182] [base:get_response] [WARNING]- Not Found: /metamap/style.css
2016-07-25 11:26:54,563 [Thread-39:-1321911488] [django.request:182] [base:get_response] [WARNING]- Not Found: /metamap/etls/execlog/29/style.css
2016-07-25 11:27:19,890 [Thread-56:-1303286976] [django.request:182] [base:get_response] [WARNING]- Not Found: /metamap/etls/execlog/29/style.css
2016-07-25 11:28:13,513 [Thread-11:-1313256640] [django.request:182] [base:get_response] [WARNING]- Not Found: /metamap/style.css
2016-07-25 11:28:17,282 [Thread-18:-1313256640] [django.request:182] [base:get_response] [WARNING]- Not Found: /metamap/etls/execlog/30/style.css
2016-07-25 11:30:22,486 [Thread-10:-1303286976] [django.request:284] [base:handle_uncaught_exception] [ERROR]- Internal Server Error: /metamap/etls/getexeclog/30/
Traceback (most recent call last):
  File "/usr/local/lib/python2.7/dist-packages/django/core/handlers/base.py", line 149, in get_response
    response = self.process_exception_by_middleware(e, request)
  File "/usr/local/lib/python2.7/dist-packages/django/core/handlers/base.py", line 147, in get_response
    response = wrapped_callback(request, *callback_args, **callback_kwargs)
  File "/usr/local/metamap/metamap_django/metamap/views/etls.py", line 170, in get_exec_log
    with open(execution.logLocation, 'r', newline='\n') as log:
TypeError: 'newline' is an invalid keyword argument for this function
2016-07-25 11:30:27,516 [Thread-11:-1303286976] [django.request:284] [base:handle_uncaught_exception] [ERROR]- Internal Server Error: /metamap/etls/getexeclog/30/
Traceback (most recent call last):
  File "/usr/local/lib/python2.7/dist-packages/django/core/handlers/base.py", line 149, in get_response
    response = self.process_exception_by_middleware(e, request)
  File "/usr/local/lib/python2.7/dist-packages/django/core/handlers/base.py", line 147, in get_response
    response = wrapped_callback(request, *callback_args, **callback_kwargs)
  File "/usr/local/metamap/metamap_django/metamap/views/etls.py", line 170, in get_exec_log
    with open(execution.logLocation, 'r', newline='\n') as log:
TypeError: 'newline' is an invalid keyword argument for this function
2016-07-25 11:30:32,432 [Thread-12:-1303286976] [django.request:284] [base:handle_uncaught_exception] [ERROR]- Internal Server Error: /metamap/etls/getexeclog/30/
Traceback (most recent call last):
  File "/usr/local/lib/python2.7/dist-packages/django/core/handlers/base.py", line 149, in get_response
    response = self.process_exception_by_middleware(e, request)
  File "/usr/local/lib/python2.7/dist-packages/django/core/handlers/base.py", line 147, in get_response
    response = wrapped_callback(request, *callback_args, **callback_kwargs)
  File "/usr/local/metamap/metamap_django/metamap/views/etls.py", line 170, in get_exec_log
    with open(execution.logLocation, 'r', newline='\n') as log:
TypeError: 'newline' is an invalid keyword argument for this function
2016-07-25 11:30:37,441 [Thread-13:-1303286976] [django.request:284] [base:handle_uncaught_exception] [ERROR]- Internal Server Error: /metamap/etls/getexeclog/30/
Traceback (most recent call last):
  File "/usr/local/lib/python2.7/dist-packages/django/core/handlers/base.py", line 149, in get_response
    response = self.process_exception_by_middleware(e, request)
  File "/usr/local/lib/python2.7/dist-packages/django/core/handlers/base.py", line 147, in get_response
    response = wrapped_callback(request, *callback_args, **callback_kwargs)
  File "/usr/local/metamap/metamap_django/metamap/views/etls.py", line 170, in get_exec_log
    with open(execution.logLocation, 'r', newline='\n') as log:
TypeError: 'newline' is an invalid keyword argument for this function
2016-07-25 11:30:42,436 [Thread-14:-1303286976] [django.request:284] [base:handle_uncaught_exception] [ERROR]- Internal Server Error: /metamap/etls/getexeclog/30/
Traceback (most recent call last):
  File "/usr/local/lib/python2.7/dist-packages/django/core/handlers/base.py", line 149, in get_response
    response = self.process_exception_by_middleware(e, request)
  File "/usr/local/lib/python2.7/dist-packages/django/core/handlers/base.py", line 147, in get_response
    response = wrapped_callback(request, *callback_args, **callback_kwargs)
  File "/usr/local/metamap/metamap_django/metamap/views/etls.py", line 170, in get_exec_log
    with open(execution.logLocation, 'r', newline='\n') as log:
TypeError: 'newline' is an invalid keyword argument for this function
2016-07-25 11:30:47,431 [Thread-15:-1303286976] [django.request:284] [base:handle_uncaught_exception] [ERROR]- Internal Server Error: /metamap/etls/getexeclog/30/
Traceback (most recent call last):
  File "/usr/local/lib/python2.7/dist-packages/django/core/handlers/base.py", line 149, in get_response
    response = self.process_exception_by_middleware(e, request)
  File "/usr/local/lib/python2.7/dist-packages/django/core/handlers/base.py", line 147, in get_response
    response = wrapped_callback(request, *callback_args, **callback_kwargs)
  File "/usr/local/metamap/metamap_django/metamap/views/etls.py", line 170, in get_exec_log
    with open(execution.logLocation, 'r', newline='\n') as log:
TypeError: 'newline' is an invalid keyword argument for this function
2016-07-25 11:30:52,432 [Thread-16:-1303286976] [django.request:284] [base:handle_uncaught_exception] [ERROR]- Internal Server Error: /metamap/etls/getexeclog/30/
Traceback (most recent call last):
  File "/usr/local/lib/python2.7/dist-packages/django/core/handlers/base.py", line 149, in get_response
    response = self.process_exception_by_middleware(e, request)
  File "/usr/local/lib/python2.7/dist-packages/django/core/handlers/base.py", line 147, in get_response
    response = wrapped_callback(request, *callback_args, **callback_kwargs)
  File "/usr/local/metamap/metamap_django/metamap/views/etls.py", line 170, in get_exec_log
    with open(execution.logLocation, 'r', newline='\n') as log:
TypeError: 'newline' is an invalid keyword argument for this function
2016-07-25 11:30:57,436 [Thread-17:-1303286976] [django.request:284] [base:handle_uncaught_exception] [ERROR]- Internal Server Error: /metamap/etls/getexeclog/30/
Traceback (most recent call last):
  File "/usr/local/lib/python2.7/dist-packages/django/core/handlers/base.py", line 149, in get_response
    response = self.process_exception_by_middleware(e, request)
  File "/usr/local/lib/python2.7/dist-packages/django/core/handlers/base.py", line 147, in get_response
    response = wrapped_callback(request, *callback_args, **callback_kwargs)
  File "/usr/local/metamap/metamap_django/metamap/views/etls.py", line 170, in get_exec_log
    with open(execution.logLocation, 'r', newline='\n') as log:
TypeError: 'newline' is an invalid keyword argument for this function
2016-07-25 11:31:02,430 [Thread-18:-1313518784] [django.request:284] [base:handle_uncaught_exception] [ERROR]- Internal Server Error: /metamap/etls/getexeclog/30/
Traceback (most recent call last):
  File "/usr/local/lib/python2.7/dist-packages/django/core/handlers/base.py", line 149, in get_response
    response = self.process_exception_by_middleware(e, request)
  File "/usr/local/lib/python2.7/dist-packages/django/core/handlers/base.py", line 147, in get_response
    response = wrapped_callback(request, *callback_args, **callback_kwargs)
  File "/usr/local/metamap/metamap_django/metamap/views/etls.py", line 170, in get_exec_log
    with open(execution.logLocation, 'r', newline='\n') as log:
TypeError: 'newline' is an invalid keyword argument for this function
2016-07-25 11:31:07,442 [Thread-19:-1313518784] [django.request:284] [base:handle_uncaught_exception] [ERROR]- Internal Server Error: /metamap/etls/getexeclog/30/
Traceback (most recent call last):
  File "/usr/local/lib/python2.7/dist-packages/django/core/handlers/base.py", line 149, in get_response
    response = self.process_exception_by_middleware(e, request)
  File "/usr/local/lib/python2.7/dist-packages/django/core/handlers/base.py", line 147, in get_response
    response = wrapped_callback(request, *callback_args, **callback_kwargs)
  File "/usr/local/metamap/metamap_django/metamap/views/etls.py", line 170, in get_exec_log
    with open(execution.logLocation, 'r', newline='\n') as log:
TypeError: 'newline' is an invalid keyword argument for this function
2016-07-25 11:31:12,429 [Thread-20:-1313518784] [django.request:284] [base:handle_uncaught_exception] [ERROR]- Internal Server Error: /metamap/etls/getexeclog/30/
Traceback (most recent call last):
  File "/usr/local/lib/python2.7/dist-packages/django/core/handlers/base.py", line 149, in get_response
    response = self.process_exception_by_middleware(e, request)
  File "/usr/local/lib/python2.7/dist-packages/django/core/handlers/base.py", line 147, in get_response
    response = wrapped_callback(request, *callback_args, **callback_kwargs)
  File "/usr/local/metamap/metamap_django/metamap/views/etls.py", line 170, in get_exec_log
    with open(execution.logLocation, 'r', newline='\n') as log:
TypeError: 'newline' is an invalid keyword argument for this function
2016-07-25 11:31:17,498 [Thread-22:-1313518784] [django.request:182] [base:get_response] [WARNING]- Not Found: /metamap/etls/execlog/30/style.css
2016-07-25 11:31:19,321 [Thread-24:-1321911488] [django.request:182] [base:get_response] [WARNING]- Not Found: /metamap/etls/execlog/30/style.css
2016-07-25 11:31:24,456 [Thread-27:-1330304192] [django.request:284] [base:handle_uncaught_exception] [ERROR]- Internal Server Error: /metamap/etls/getexeclog/30/
Traceback (most recent call last):
  File "/usr/local/lib/python2.7/dist-packages/django/core/handlers/base.py", line 149, in get_response
    response = self.process_exception_by_middleware(e, request)
  File "/usr/local/lib/python2.7/dist-packages/django/core/handlers/base.py", line 147, in get_response
    response = wrapped_callback(request, *callback_args, **callback_kwargs)
  File "/usr/local/metamap/metamap_django/metamap/views/etls.py", line 170, in get_exec_log
    with open(execution.logLocation, 'r', newline='\n') as log:
TypeError: 'newline' is an invalid keyword argument for this function
2016-07-25 11:31:29,431 [Thread-28:-1330304192] [django.request:284] [base:handle_uncaught_exception] [ERROR]- Internal Server Error: /metamap/etls/getexeclog/30/
Traceback (most recent call last):
  File "/usr/local/lib/python2.7/dist-packages/django/core/handlers/base.py", line 149, in get_response
    response = self.process_exception_by_middleware(e, request)
  File "/usr/local/lib/python2.7/dist-packages/django/core/handlers/base.py", line 147, in get_response
    response = wrapped_callback(request, *callback_args, **callback_kwargs)
  File "/usr/local/metamap/metamap_django/metamap/views/etls.py", line 170, in get_exec_log
    with open(execution.logLocation, 'r', newline='\n') as log:
TypeError: 'newline' is an invalid keyword argument for this function
2016-07-25 11:31:34,813 [Thread-29:-1330304192] [django.request:284] [base:handle_uncaught_exception] [ERROR]- Internal Server Error: /metamap/etls/getexeclog/30/
Traceback (most recent call last):
  File "/usr/local/lib/python2.7/dist-packages/django/core/handlers/base.py", line 149, in get_response
    response = self.process_exception_by_middleware(e, request)
  File "/usr/local/lib/python2.7/dist-packages/django/core/handlers/base.py", line 147, in get_response
    response = wrapped_callback(request, *callback_args, **callback_kwargs)
  File "/usr/local/metamap/metamap_django/metamap/views/etls.py", line 170, in get_exec_log
    with open(execution.logLocation, 'r', newline='\n') as log:
TypeError: 'newline' is an invalid keyword argument for this function
2016-07-25 11:31:39,432 [Thread-30:-1330304192] [django.request:284] [base:handle_uncaught_exception] [ERROR]- Internal Server Error: /metamap/etls/getexeclog/30/
Traceback (most recent call last):
  File "/usr/local/lib/python2.7/dist-packages/django/core/handlers/base.py", line 149, in get_response
    response = self.process_exception_by_middleware(e, request)
  File "/usr/local/lib/python2.7/dist-packages/django/core/handlers/base.py", line 147, in get_response
    response = wrapped_callback(request, *callback_args, **callback_kwargs)
  File "/usr/local/metamap/metamap_django/metamap/views/etls.py", line 170, in get_exec_log
    with open(execution.logLocation, 'r', newline='\n') as log:
TypeError: 'newline' is an invalid keyword argument for this function
2016-07-25 11:31:44,438 [Thread-31:-1330304192] [django.request:284] [base:handle_uncaught_exception] [ERROR]- Internal Server Error: /metamap/etls/getexeclog/30/
Traceback (most recent call last):
  File "/usr/local/lib/python2.7/dist-packages/django/core/handlers/base.py", line 149, in get_response
    response = self.process_exception_by_middleware(e, request)
  File "/usr/local/lib/python2.7/dist-packages/django/core/handlers/base.py", line 147, in get_response
    response = wrapped_callback(request, *callback_args, **callback_kwargs)
  File "/usr/local/metamap/metamap_django/metamap/views/etls.py", line 170, in get_exec_log
    with open(execution.logLocation, 'r', newline='\n') as log:
TypeError: 'newline' is an invalid keyword argument for this function
2016-07-25 11:31:49,431 [Thread-32:-1330304192] [django.request:284] [base:handle_uncaught_exception] [ERROR]- Internal Server Error: /metamap/etls/getexeclog/30/
Traceback (most recent call last):
  File "/usr/local/lib/python2.7/dist-packages/django/core/handlers/base.py", line 149, in get_response
    response = self.process_exception_by_middleware(e, request)
  File "/usr/local/lib/python2.7/dist-packages/django/core/handlers/base.py", line 147, in get_response
    response = wrapped_callback(request, *callback_args, **callback_kwargs)
  File "/usr/local/metamap/metamap_django/metamap/views/etls.py", line 170, in get_exec_log
    with open(execution.logLocation, 'r', newline='\n') as log:
TypeError: 'newline' is an invalid keyword argument for this function
2016-07-25 11:31:54,442 [Thread-33:-1330304192] [django.request:284] [base:handle_uncaught_exception] [ERROR]- Internal Server Error: /metamap/etls/getexeclog/30/
Traceback (most recent call last):
  File "/usr/local/lib/python2.7/dist-packages/django/core/handlers/base.py", line 149, in get_response
    response = self.process_exception_by_middleware(e, request)
  File "/usr/local/lib/python2.7/dist-packages/django/core/handlers/base.py", line 147, in get_response
    response = wrapped_callback(request, *callback_args, **callback_kwargs)
  File "/usr/local/metamap/metamap_django/metamap/views/etls.py", line 170, in get_exec_log
    with open(execution.logLocation, 'r', newline='\n') as log:
TypeError: 'newline' is an invalid keyword argument for this function
2016-07-25 11:31:59,430 [Thread-34:-1330304192] [django.request:284] [base:handle_uncaught_exception] [ERROR]- Internal Server Error: /metamap/etls/getexeclog/30/
Traceback (most recent call last):
  File "/usr/local/lib/python2.7/dist-packages/django/core/handlers/base.py", line 149, in get_response
    response = self.process_exception_by_middleware(e, request)
  File "/usr/local/lib/python2.7/dist-packages/django/core/handlers/base.py", line 147, in get_response
    response = wrapped_callback(request, *callback_args, **callback_kwargs)
  File "/usr/local/metamap/metamap_django/metamap/views/etls.py", line 170, in get_exec_log
    with open(execution.logLocation, 'r', newline='\n') as log:
TypeError: 'newline' is an invalid keyword argument for this function
2016-07-25 11:32:04,438 [Thread-35:-1330304192] [django.request:284] [base:handle_uncaught_exception] [ERROR]- Internal Server Error: /metamap/etls/getexeclog/30/
Traceback (most recent call last):
  File "/usr/local/lib/python2.7/dist-packages/django/core/handlers/base.py", line 149, in get_response
    response = self.process_exception_by_middleware(e, request)
  File "/usr/local/lib/python2.7/dist-packages/django/core/handlers/base.py", line 147, in get_response
    response = wrapped_callback(request, *callback_args, **callback_kwargs)
  File "/usr/local/metamap/metamap_django/metamap/views/etls.py", line 170, in get_exec_log
    with open(execution.logLocation, 'r', newline='\n') as log:
TypeError: 'newline' is an invalid keyword argument for this function
2016-07-25 11:32:12,648 [Thread-41:-1303286976] [django.request:284] [base:handle_uncaught_exception] [ERROR]- Internal Server Error: /metamap/etls/getexeclog/30/
Traceback (most recent call last):
  File "/usr/local/lib/python2.7/dist-packages/django/core/handlers/base.py", line 149, in get_response
    response = self.process_exception_by_middleware(e, request)
  File "/usr/local/lib/python2.7/dist-packages/django/core/handlers/base.py", line 147, in get_response
    response = wrapped_callback(request, *callback_args, **callback_kwargs)
  File "/usr/local/metamap/metamap_django/metamap/views/etls.py", line 170, in get_exec_log
    with open(execution.logLocation, 'r', newline='\n') as log:
TypeError: 'newline' is an invalid keyword argument for this function
2016-07-25 11:32:17,623 [Thread-42:-1338696896] [django.request:284] [base:handle_uncaught_exception] [ERROR]- Internal Server Error: /metamap/etls/getexeclog/30/
Traceback (most recent call last):
  File "/usr/local/lib/python2.7/dist-packages/django/core/handlers/base.py", line 149, in get_response
    response = self.process_exception_by_middleware(e, request)
  File "/usr/local/lib/python2.7/dist-packages/django/core/handlers/base.py", line 147, in get_response
    response = wrapped_callback(request, *callback_args, **callback_kwargs)
  File "/usr/local/metamap/metamap_django/metamap/views/etls.py", line 170, in get_exec_log
    with open(execution.logLocation, 'r', newline='\n') as log:
TypeError: 'newline' is an invalid keyword argument for this function
2016-07-25 11:32:22,642 [Thread-43:-1338696896] [django.request:284] [base:handle_uncaught_exception] [ERROR]- Internal Server Error: /metamap/etls/getexeclog/30/
Traceback (most recent call last):
  File "/usr/local/lib/python2.7/dist-packages/django/core/handlers/base.py", line 149, in get_response
    response = self.process_exception_by_middleware(e, request)
  File "/usr/local/lib/python2.7/dist-packages/django/core/handlers/base.py", line 147, in get_response
    response = wrapped_callback(request, *callback_args, **callback_kwargs)
  File "/usr/local/metamap/metamap_django/metamap/views/etls.py", line 170, in get_exec_log
    with open(execution.logLocation, 'r', newline='\n') as log:
TypeError: 'newline' is an invalid keyword argument for this function
2016-07-25 11:32:27,624 [Thread-44:-1338696896] [django.request:284] [base:handle_uncaught_exception] [ERROR]- Internal Server Error: /metamap/etls/getexeclog/30/
Traceback (most recent call last):
  File "/usr/local/lib/python2.7/dist-packages/django/core/handlers/base.py", line 149, in get_response
    response = self.process_exception_by_middleware(e, request)
  File "/usr/local/lib/python2.7/dist-packages/django/core/handlers/base.py", line 147, in get_response
    response = wrapped_callback(request, *callback_args, **callback_kwargs)
  File "/usr/local/metamap/metamap_django/metamap/views/etls.py", line 170, in get_exec_log
    with open(execution.logLocation, 'r', newline='\n') as log:
TypeError: 'newline' is an invalid keyword argument for this function
2016-07-25 11:32:32,626 [Thread-45:-1338696896] [django.request:284] [base:handle_uncaught_exception] [ERROR]- Internal Server Error: /metamap/etls/getexeclog/30/
Traceback (most recent call last):
  File "/usr/local/lib/python2.7/dist-packages/django/core/handlers/base.py", line 149, in get_response
    response = self.process_exception_by_middleware(e, request)
  File "/usr/local/lib/python2.7/dist-packages/django/core/handlers/base.py", line 147, in get_response
    response = wrapped_callback(request, *callback_args, **callback_kwargs)
  File "/usr/local/metamap/metamap_django/metamap/views/etls.py", line 170, in get_exec_log
    with open(execution.logLocation, 'r', newline='\n') as log:
TypeError: 'newline' is an invalid keyword argument for this function
2016-07-25 11:32:37,660 [Thread-10:-1303024832] [django.request:284] [base:handle_uncaught_exception] [ERROR]- Internal Server Error: /metamap/etls/getexeclog/30/
Traceback (most recent call last):
  File "/usr/local/lib/python2.7/dist-packages/django/core/handlers/base.py", line 149, in get_response
    response = self.process_exception_by_middleware(e, request)
  File "/usr/local/lib/python2.7/dist-packages/django/core/handlers/base.py", line 147, in get_response
    response = wrapped_callback(request, *callback_args, **callback_kwargs)
  File "/usr/local/metamap/metamap_django/metamap/views/etls.py", line 170, in get_exec_log
    with open(execution.logLocation, mode='r', newline='\n') as log:
TypeError: 'newline' is an invalid keyword argument for this function
